<?xml version="1.0" encoding="utf-8"?>
<!-- This URDF was automatically created by SolidWorks to URDF Exporter! Originally created by Stephen Brawner (brawner@gmail.com) 
     Commit Version: 1.6.0-4-g7f85cfe  Build Version: 1.6.7995.38578
     For more information, please see http://wiki.ros.org/sw_urdf_exporter -->
<robot
  name="dal_amr_urdf">
  <link
    name="base_link">
    <inertial>
      <origin
        xyz="0.0261575409542285 0.0210741657149634 0.365123634271317"
        rpy="0 0 0" />
      <mass
        value="1106.06131565097" />
      <inertia
        ixx="30.0661765809516"
        ixy="-0.0415848299592544"
        ixz="-0.532388348720607"
        iyy="28.7861928638338"
        iyz="0.0642938407349405"
        izz="48.0522649837224" />
    </inertial>
    <visual>
      <origin
        xyz="0 0 0"
        rpy="0 0 0" />
      <geometry>
        <mesh
          filename="package://dal_amr_urdf/meshes/base_link.STL" />
      </geometry>
      <material
        name="">
        <color
          rgba="0.752941176470588 0.752941176470588 0.752941176470588 1" />
      </material>
    </visual>
    <collision>
      <origin
        xyz="0 0 0"
        rpy="0 0 0" />
      <geometry>
        <mesh
          filename="package://dal_amr_urdf/meshes/base_link.STL" />
      </geometry>
    </collision>
  </link>
  <link
    name="R-R_wheel_link">
    <inertial>
      <origin
        xyz="0.000837352294780658 0.0749999715872502 -2.07542278129191E-05"
        rpy="0 0 0" />
      <mass
        value="10.8599966757081" />
      <inertia
        ixx="0.045945320384186"
        ixy="1.41212967220304E-08"
        ixz="2.05474074273E-06"
        iyy="0.0755405083831593"
        iyz="-2.96567149974496E-08"
        izz="0.0459505223952201" />
    </inertial>
    <visual>
      <origin
        xyz="0 0 0"
        rpy="0 0 0" />
      <geometry>
        <mesh
          filename="package://dal_amr_urdf/meshes/R-R_wheel_link.STL" />
      </geometry>
      <material
        name="">
        <color
          rgba="0.752941176470588 0.752941176470588 0.752941176470588 1" />
      </material>
    </visual>
    <collision>
      <origin
        xyz="0 0 0"
        rpy="0 0 0" />
      <geometry>
        <mesh
          filename="package://dal_amr_urdf/meshes/R-R_wheel_link.STL" />
      </geometry>
    </collision>
  </link>
  <joint
    name="R-R_wheel_joint"
    type="continuous">
    <origin
      xyz="-0.60085 -1.001 0.18751"
      rpy="0 0 0" />
    <parent
      link="base_link" />
    <child
      link="R-R_wheel_link" />
    <axis
      xyz="0 1 0" />
  </joint>
  <link
    name="R-F_wheel_link">
    <inertial>
      <origin
        xyz="0.000861331215957328 0.0750000221750111 -1.58733124274724E-05"
        rpy="0 0 0" />
      <mass
        value="10.8599965368607" />
      <inertia
        ixx="0.0459476780656675"
        ixy="-1.23349354789281E-08"
        ixz="-3.27048841674837E-06"
        iyy="0.0755405083455259"
        iyz="3.20025319341261E-08"
        izz="0.0459481647632598" />
    </inertial>
    <visual>
      <origin
        xyz="0 0 0"
        rpy="0 0 0" />
      <geometry>
        <mesh
          filename="package://dal_amr_urdf/meshes/R-F_wheel_link.STL" />
      </geometry>
      <material
        name="">
        <color
          rgba="0.752941176470588 0.752941176470588 0.752941176470588 1" />
      </material>
    </visual>
    <collision>
      <origin
        xyz="0 0 0"
        rpy="0 0 0" />
      <geometry>
        <mesh
          filename="package://dal_amr_urdf/meshes/R-F_wheel_link.STL" />
      </geometry>
    </collision>
  </link>
  <joint
    name="R-F_wheel_joint"
    type="continuous">
    <origin
      xyz="0.59915 -1.001 0.18751"
      rpy="0 0 0" />
    <parent
      link="base_link" />
    <child
      link="R-F_wheel_link" />
    <axis
      xyz="0 1 0" />
  </joint>
  <link
    name="L-R_wheel_link">
    <inertial>
      <origin
        xyz="-0.000825366428255814 -0.0749999727162008 9.57292000588333E-06"
        rpy="0 0 0" />
      <mass
        value="10.8599965274659" />
      <inertia
        ixx="0.0459502044190202"
        ixy="-3.21465114318727E-08"
        ixz="2.40441780102765E-06"
        iyy="0.0755405081550335"
        iyz="1.21842543537724E-08"
        izz="0.0459456382133598" />
    </inertial>
    <visual>
      <origin
        xyz="0 0 0"
        rpy="0 0 0" />
      <geometry>
        <mesh
          filename="package://dal_amr_urdf/meshes/L-R_wheel_link.STL" />
      </geometry>
      <material
        name="">
        <color
          rgba="0.752941176470588 0.752941176470588 0.752941176470588 1" />
      </material>
    </visual>
    <collision>
      <origin
        xyz="0 0 0"
        rpy="0 0 0" />
      <geometry>
        <mesh
          filename="package://dal_amr_urdf/meshes/L-R_wheel_link.STL" />
      </geometry>
    </collision>
  </link>
  <joint
    name="L-R_wheel_joint"
    type="continuous">
    <origin
      xyz="-0.59915 1.001 0.18751"
      rpy="0 0 0" />
    <parent
      link="base_link" />
    <child
      link="L-R_wheel_link" />
    <axis
      xyz="0 1 0" />
  </joint>
  <link
    name="L-F_wheel_link">
    <inertial>
      <origin
        xyz="-0.000829638377100927 -0.0749999778249336 -1.58733125112318E-05"
        rpy="0 0 0" />
      <mass
        value="10.8599965368607" />
      <inertia
        ixx="0.0459476780656694"
        ixy="-1.23349355073917E-08"
        ixz="-3.27048841586947E-06"
        iyy="0.0755405083455284"
        iyz="3.2002530628339E-08"
        izz="0.0459481647632625" />
    </inertial>
    <visual>
      <origin
        xyz="0 0 0"
        rpy="0 0 0" />
      <geometry>
        <mesh
          filename="package://dal_amr_urdf/meshes/L-F_wheel_link.STL" />
      </geometry>
      <material
        name="">
        <color
          rgba="0.752941176470588 0.752941176470588 0.752941176470588 1" />
      </material>
    </visual>
    <collision>
      <origin
        xyz="0 0 0"
        rpy="0 0 0" />
      <geometry>
        <mesh
          filename="package://dal_amr_urdf/meshes/L-F_wheel_link.STL" />
      </geometry>
    </collision>
  </link>
  <joint
    name="L-F_wheel_joint"
    type="continuous">
    <origin
      xyz="0.60085 1.001 0.18751"
      rpy="0 0 0" />
    <parent
      link="base_link" />
    <child
      link="L-F_wheel_link" />
    <axis
      xyz="0 1 0" />
  </joint>
</robot>