<?xml version="1.0" encoding="utf-8"?>
<!-- This URDF was automatically created by SolidWorks to URDF Exporter! Originally created by Stephen Brawner (brawner@gmail.com) 
     Commit Version: 1.6.0-4-g7f85cfe  Build Version: 1.6.7995.38578
     For more information, please see http://wiki.ros.org/sw_urdf_exporter -->
<robot
  name="dal_amr_urdf">
  <link
    name="base_link">
    <inertial>
      <origin
        xyz="0.0316059497547685 0.0522983293790818 0.371452804935302"
        rpy="0 0 0" />
      <mass
        value="1038.22966875249" />
      <inertia
        ixx="28.7881188092628"
        ixy="-0.0411635729683726"
        ixz="-0.532384536166808"
        iyy="27.9996771179143"
        iyz="0.0770360705447685"
        izz="46.1840402802839" />
    </inertial>
    <visual>
      <origin
        xyz="0 0 0"
        rpy="0 0 0" />
      <geometry>
        <mesh
          filename="package://dal_amr_urdf/meshes/base_link.STL" />
      </geometry>
      <material
        name="">
        <color
          rgba="0.752941176470588 0.752941176470588 0.752941176470588 1" />
      </material>
    </visual>
    <collision>
      <origin
        xyz="0 0 0"
        rpy="0 0 0" />
      <geometry>
        <mesh
          filename="package://dal_amr_urdf/meshes/base_link.STL" />
      </geometry>
    </collision>
  </link>
  <link
    name="R-R_wheel_link">
    <inertial>
      <origin
        xyz="0.000837352246584766 0.0749999721322621 -2.07541284918122E-05"
        rpy="0 0 0" />
      <mass
        value="10.8599966783425" />
      <inertia
        ixx="0.0459453194105337"
        ixy="1.37623720806641E-08"
        ixz="2.05677068774345E-06"
        iyy="0.0755405084811422"
        iyz="-2.97402661249492E-08"
        izz="0.045950523466665" />
    </inertial>
    <visual>
      <origin
        xyz="0 0 0"
        rpy="0 0 0" />
      <geometry>
        <mesh
          filename="package://dal_amr_urdf/meshes/R-R_wheel_link.STL" />
      </geometry>
      <material
        name="">
        <color
          rgba="0.752941176470588 0.752941176470588 0.752941176470588 1" />
      </material>
    </visual>
    <collision>
      <origin
        xyz="0 0 0"
        rpy="0 0 0" />
      <geometry>
        <mesh
          filename="package://dal_amr_urdf/meshes/R-R_wheel_link.STL" />
      </geometry>
    </collision>
  </link>
  <joint
    name="R-R_wheel_joint"
    type="continuous">
    <origin
      xyz="-0.600845484796538 -1.00098987276654 0.187510000000006"
      rpy="0 0 0" />
    <parent
      link="base_link" />
    <child
      link="R-R_wheel_link" />
    <axis
      xyz="0 1 0" />
  </joint>
  <link
    name="R-F_wheel_link">
    <inertial>
      <origin
        xyz="0.000861331215951111 0.0750000221750111 -1.5873312427403E-05"
        rpy="0 0 0" />
      <mass
        value="10.8599965368607" />
      <inertia
        ixx="0.0459476780656676"
        ixy="-1.23349354785215E-08"
        ixz="-3.27048841674847E-06"
        iyy="0.0755405083455259"
        iyz="3.20025319339671E-08"
        izz="0.0459481647632598" />
    </inertial>
    <visual>
      <origin
        xyz="0 0 0"
        rpy="0 0 0" />
      <geometry>
        <mesh
          filename="package://dal_amr_urdf/meshes/R-F_wheel_link.STL" />
      </geometry>
      <material
        name="">
        <color
          rgba="0.752941176470588 0.752941176470588 0.752941176470588 1" />
      </material>
    </visual>
    <collision>
      <origin
        xyz="0 0 0"
        rpy="0 0 0" />
      <geometry>
        <mesh
          filename="package://dal_amr_urdf/meshes/R-F_wheel_link.STL" />
      </geometry>
    </collision>
  </link>
  <joint
    name="R-F_wheel_joint"
    type="continuous">
    <origin
      xyz="0.599154515203462 -1.00098987276653 0.187510000000006"
      rpy="0 0 0" />
    <parent
      link="base_link" />
    <child
      link="R-F_wheel_link" />
    <axis
      xyz="0 1 0" />
  </joint>
  <link
    name="L-R_wheel_link">
    <inertial>
      <origin
        xyz="-0.000825366428256702 -0.0749999727162015 9.57292000592497E-06"
        rpy="0 0 0" />
      <mass
        value="10.8599965274659" />
      <inertia
        ixx="0.0459502044190201"
        ixy="-3.21465114318546E-08"
        ixz="2.40441780102781E-06"
        iyy="0.0755405081550335"
        iyz="1.21842543538674E-08"
        izz="0.0459456382133597" />
    </inertial>
    <visual>
      <origin
        xyz="0 0 0"
        rpy="0 0 0" />
      <geometry>
        <mesh
          filename="package://dal_amr_urdf/meshes/L-R_wheel_link.STL" />
      </geometry>
      <material
        name="">
        <color
          rgba="0.752941176470588 0.752941176470588 0.752941176470588 1" />
      </material>
    </visual>
    <collision>
      <origin
        xyz="0 0 0"
        rpy="0 0 0" />
      <geometry>
        <mesh
          filename="package://dal_amr_urdf/meshes/L-R_wheel_link.STL" />
      </geometry>
    </collision>
  </link>
  <joint
    name="L-R_wheel_joint"
    type="continuous">
    <origin
      xyz="-0.599154515203465 1.00101012723346 0.187510000000002"
      rpy="0 0 0" />
    <parent
      link="base_link" />
    <child
      link="L-R_wheel_link" />
    <axis
      xyz="0 1 0" />
  </joint>
  <link
    name="L-F_wheel_link">
    <inertial>
      <origin
        xyz="-0.00082963837710226 -0.0749999778249339 -1.58733125112387E-05"
        rpy="0 0 0" />
      <mass
        value="10.8599965368607" />
      <inertia
        ixx="0.0459476780656694"
        ixy="-1.23349355069363E-08"
        ixz="-3.27048841586989E-06"
        iyy="0.0755405083455284"
        iyz="3.2002530628003E-08"
        izz="0.0459481647632624" />
    </inertial>
    <visual>
      <origin
        xyz="0 0 0"
        rpy="0 0 0" />
      <geometry>
        <mesh
          filename="package://dal_amr_urdf/meshes/L-F_wheel_link.STL" />
      </geometry>
      <material
        name="">
        <color
          rgba="0.752941176470588 0.752941176470588 0.752941176470588 1" />
      </material>
    </visual>
    <collision>
      <origin
        xyz="0 0 0"
        rpy="0 0 0" />
      <geometry>
        <mesh
          filename="package://dal_amr_urdf/meshes/L-F_wheel_link.STL" />
      </geometry>
    </collision>
  </link>
  <joint
    name="L-F_wheel_joint"
    type="continuous">
    <origin
      xyz="0.600845484796534 1.00101012723347 0.187510000000002"
      rpy="0 0 0" />
    <parent
      link="base_link" />
    <child
      link="L-F_wheel_link" />
    <axis
      xyz="0 1 0" />
  </joint>
  <link
    name="laser_link">
    <inertial>
      <origin
        xyz="7.54806509739581E-06 0.000904387104687432 -0.0378632905447971"
        rpy="0 0 0" />
      <mass
        value="0.786331372661155" />
      <inertia
        ixx="0.00127802962224358"
        ixy="-2.72188723629953E-07"
        ixz="1.91076054940038E-07"
        iyy="0.00124699055332785"
        iyz="5.36961290093264E-06"
        izz="0.00109111857909312" />
    </inertial>
    <visual>
      <origin
        xyz="0 0 0"
        rpy="0 0 0" />
      <geometry>
        <mesh
          filename="package://dal_amr_urdf/meshes/laser_link.STL" />
      </geometry>
      <material
        name="">
        <color
          rgba="0.752941176470588 0.752941176470588 0.752941176470588 1" />
      </material>
    </visual>
    <collision>
      <origin
        xyz="0 0 0"
        rpy="0 0 0" />
      <geometry>
        <mesh
          filename="package://dal_amr_urdf/meshes/laser_link.STL" />
      </geometry>
    </collision>
  </link>
  <joint
    name="laser_joint"
    type="fixed">
    <origin
      xyz="0.76499999485128 -0.739989872766514 0.567510000000008"
      rpy="0 0 0" />
    <parent
      link="base_link" />
    <child
      link="laser_link" />
    <axis
      xyz="0 0 0" />
  </joint>
  <link
    name="laser_link2">
    <inertial>
      <origin
        xyz="7.54806511338302E-06 0.000904387104687543 -0.0378632905448119"
        rpy="0 0 0" />
      <mass
        value="0.786331372661179" />
      <inertia
        ixx="0.00127802962224363"
        ixy="-2.72188723627625E-07"
        ixz="1.91076054939852E-07"
        iyy="0.00124699055332789"
        iyz="5.36961290094664E-06"
        izz="0.00109111857909316" />
    </inertial>
    <visual>
      <origin
        xyz="0 0 0"
        rpy="0 0 0" />
      <geometry>
        <mesh
          filename="package://dal_amr_urdf/meshes/laser_link2.STL" />
      </geometry>
      <material
        name="">
        <color
          rgba="0.752941176470588 0.752941176470588 0.752941176470588 1" />
      </material>
    </visual>
    <collision>
      <origin
        xyz="0 0 0"
        rpy="0 0 0" />
      <geometry>
        <mesh
          filename="package://dal_amr_urdf/meshes/laser_link2.STL" />
      </geometry>
    </collision>
  </link>
  <joint
    name="laser_joint2"
    type="fixed">
    <origin
      xyz="-0.765000005148736 -0.733989872766535 0.567509999999994"
      rpy="0 0 0" />
    <parent
      link="base_link" />
    <child
      link="laser_link2" />
    <axis
      xyz="0 0 0" />
  </joint>
  <link
    name="imu_link">
    <inertial>
      <origin
        xyz="-1.38745353872594E-07 3.73954120880815E-05 0.0079823347361489"
        rpy="0 0 0" />
      <mass
        value="0.0184458621702854" />
      <inertia
        ixx="2.16462683910551E-06"
        ixy="-7.35169180692452E-11"
        ixz="1.64418721935121E-11"
        iyy="2.17243034491282E-06"
        iyz="-4.4954171391151E-09"
        izz="3.55221693439667E-06" />
    </inertial>
    <visual>
      <origin
        xyz="0 0 0"
        rpy="0 0 0" />
      <geometry>
        <mesh
          filename="package://dal_amr_urdf/meshes/imu_link.STL" />
      </geometry>
      <material
        name="">
        <color
          rgba="0.792156862745098 0.819607843137255 0.933333333333333 1" />
      </material>
    </visual>
    <collision>
      <origin
        xyz="0 0 0"
        rpy="0 0 0" />
      <geometry>
        <mesh
          filename="package://dal_amr_urdf/meshes/imu_link.STL" />
      </geometry>
    </collision>
  </link>
  <joint
    name="imu_joint"
    type="fixed">
    <origin
      xyz="0.818000000000031 -0.236989872766201 0.485510000000965"
      rpy="0 0 0" />
    <parent
      link="base_link" />
    <child
      link="imu_link" />
    <axis
      xyz="0 0 0" />
  </joint>
</robot>